File: xrd/test.xrdml
<?xml version="1.0" encoding="UTF-8"?>
<xrdMeasurements xmlns="http://www.xrdml.com/XRDMeasurement/1.0" xmlns:xsi="http://www.w3.org/2001/XMLSchema-instance" xsi:schemaLocation="http://www.xrdml.com/XRDMeasurement/1.0 http://www.xrdml.com/XRDMeasurement/1.0/XRDMeasurement.xsd" status="Completed">
	<sample type="To be analyzed">
		<id>B11091</id>
	</sample>
	<xrdMeasurement measurementType="Area measurement" status="Completed" measurementStepAxis="Omega">
		<comment>
			<entry/>
		</comment>
		<usedWavelength intended="K-Alpha 1">
			<kAlpha1 unit="Angstrom">1.5405980</kAlpha1>
			<kAlpha2 unit="Angstrom">1.5444260</kAlpha2>
			<kBeta unit="Angstrom">1.3922500</kBeta>
			<ratioKAlpha2KAlpha1>0.5000</ratioKAlpha2KAlpha1>
		</usedWavelength>
		<incidentBeamPath>
			<radius unit="mm">320.00</radius>
			<xRayTube id="1010048" name="PW3373/10 Cu LFF DK392924">
				<tension unit="kV">45</tension>
				<current unit="mA">40</current>
				<anodeMaterial>Cu</anodeMaterial>
				<focus type="Line">
					<length unit="mm">12.0</length>
					<width unit="mm">0.4</width>
					<takeOffAngle unit="deg">3.3</takeOffAngle>
				</focus>
			</xRayTube>
			<xRayMirror id="27010001" name="Inc. X-ray mirror Cu (MRD)" hybrid="false">
				<crystal type="Graded" shape="Parabolic">W/Si</crystal>
				<acceptanceAngle unit="deg">0.8</acceptanceAngle>
				<length unit="mm">60.0</length>
			</xRayMirror>
			<divergenceSlit id="22010005" name="Slit Fixed 1/4Â°" xsi:type="fixedDivergenceSlitType">
				<height unit="mm">0.38</height>
			</divergenceSlit>
			<beamAttenuator id="26010001" name="Ni 0.125 mm automatic" xsi:type="intensitySwitchedBeamAttenuatorType">
				<factor>149.50</factor>
				<material>Ni</material>
				<activateLevel unit="counts per second">500000</activateLevel>
				<deactivateLevel unit="counts per second">400000</deactivateLevel>
			</beamAttenuator>
		</incidentBeamPath>
		<sampleOffset>
			<position axis="2Theta" unit="deg">0.0092</position>
			<position axis="Omega" unit="deg">-0.8913</position>
			<position axis="Psi" unit="deg">0.35</position>
		</sampleOffset>
		<diffractedBeamPath>
			<radius unit="mm">320.00</radius>
			<antiScatterSlit id="22060009" name="Prog. AS Slit" xsi:type="fixedAntiScatterSlitType">
				<height unit="mm">0.80</height>
			</antiScatterSlit>
			<receivingSlit id="22020009" name="Prog. Rec. Slit">
				<height unit="mm">0.80</height>
			</receivingSlit>
			<detector id="7010011" name="PW3011/20 (Miniprop. large window)" xsi:type="pointDetectorType">
				<phd>
					<lowerLevel unit="%">35.0</lowerLevel>
					<upperLevel unit="%">80.0</upperLevel>
				</phd>
			</detector>
		</diffractedBeamPath>
		<measurementStepAxisCenter>
			<position axis="Omega" unit="deg">19.5666</position>
		</measurementStepAxisCenter>
		<scan appendNumber="0" mode="Continuous" scanAxis="Omega-2Theta" status="Completed">
			<header>
				<startTimeStamp>2011-04-25T15:47:05+02:00</startTimeStamp>
				<endTimeStamp>2011-04-25T15:51:16+02:00</endTimeStamp>
				<author>
					<name>Mesures</name>
				</author>
				<source>
					<applicationSoftware version="2.0e">X'Pert Data Collector</applicationSoftware>
					<instrumentControlSoftware version="1.5 ">XPERT-PRO</instrumentControlSoftware>
					<instrumentID>0000000098722659</instrumentID>
				</source>
			</header>
			<scanAxisCenter>
				<position axis="2Theta" unit="deg">76.0000</position>
				<position axis="Omega" unit="deg">18.0666</position>
			</scanAxisCenter>
			<reflection>
				<material>SrTiO3</material>
				<hkl>
					<h>0</h>
					<k>1</k>
					<l>3</l>
				</hkl>
			</reflection>
			<dataPoints>
				<positions axis="2Theta" unit="deg">
					<startPosition>73.0400</startPosition>
					<endPosition>78.9600</endPosition>
				</positions>
				<positions axis="Omega" unit="deg">
					<startPosition>16.5866</startPosition>
					<endPosition>19.5466</endPosition>
				</positions>
				<positions axis="Phi" unit="deg">
					<commonPosition>0.00</commonPosition>
				</positions>
				<positions axis="Psi" unit="deg">
					<commonPosition>-0.40</commonPosition>
				</positions>
				<positions axis="X" unit="mm">
					<commonPosition>2.37</commonPosition>
				</positions>
				<positions axis="Y" unit="mm">
					<commonPosition>-0.98</commonPosition>
				</positions>
				<positions axis="Z" unit="mm">
					<commonPosition>9.695</commonPosition>
				</positions>
				<beamAttenuationFactors>1.00 1.00 1.00 1.00 1.00 1.00 1.00 1.00 1.00 1.00 1.00 1.00 1.00 1.00 1.00 1.00 1.00 1.00 1.00 1.00 1.00 1.00 1.00 1.00 1.00 1.00 1.00 1.00 1.00 1.00 1.00 1.00 1.00 1.00 1.00 1.00 1.00 1.00 1.00 1.00 1.00 1.00 1.00 1.00 1.00 1.00 1.00 1.00 1.00 1.00 1.00 1.00 1.00 1.00 1.00 1.00 1.00 1.00 1.00 1.00 1.00 1.00 1.00 1.00 1.00 1.00 1.00 1.00 1.00 1.00 1.00 1.00 1.00 1.00 1.00</beamAttenuationFactors>
				<commonCountingTime unit="seconds">3.00</commonCountingTime>
				<intensities unit="counts">13 14 10 10 9 12 17 11 19 12 11 18 10 12 12 12 9 14 13 16 9 11 5 13 8 3 2 9 6 10 11 5 7 11 4 6 7 4 6 6 3 8 7 3 7 7 9 6 11 7 5 7 9 10 9 12 6 3 5 2 6 2 3 8 4 2 9 3 1 5 7 6 5 5 4</intensities>
			</dataPoints>
		</scan>
		<scan appendNumber="0" mode="Continuous" scanAxis="Omega-2Theta" status="Completed">
			<header>
				<startTimeStamp>2011-04-25T15:51:29+02:00</startTimeStamp>
				<endTimeStamp>2011-04-25T15:55:40+02:00</endTimeStamp>
				<author>
					<name>Mesures</name>
				</author>
				<source>
					<applicationSoftware version="2.0e">X'Pert Data Collector</applicationSoftware>
					<instrumentControlSoftware version="1.5 ">XPERT-PRO</instrumentControlSoftware>
					<instrumentID>0000000098722659</instrumentID>
				</source>
			</header>
			<scanAxisCenter>
				<position axis="2Theta" unit="deg">76.0000</position>
				<position axis="Omega" unit="deg">18.1066</position>
			</scanAxisCenter>
			<reflection>
				<material>SrTiO3</material>
				<hkl>
					<h>0</h>
					<k>1</k>
					<l>3</l>
				</hkl>
			</reflection>
			<dataPoints>
				<positions axis="2Theta" unit="deg">
					<startPosition>73.0400</startPosition>
					<endPosition>78.9600</endPosition>
				</positions>
				<positions axis="Omega" unit="deg">
					<startPosition>16.6266</startPosition>
					<endPosition>19.5866</endPosition>
				</positions>
				<positions axis="Phi" unit="deg">
					<commonPosition>0.00</commonPosition>
				</positions>
				<positions axis="Psi" unit="deg">
					<commonPosition>-0.40</commonPosition>
				</positions>
				<positions axis="X" unit="mm">
					<commonPosition>2.37</commonPosition>
				</positions>
				<positions axis="Y" unit="mm">
					<commonPosition>-0.98</commonPosition>
				</positions>
				<positions axis="Z" unit="mm">
					<commonPosition>9.695</commonPosition>
				</positions>
				<beamAttenuationFactors>1.00 1.00 1.00 1.00 1.00 1.00 1.00 1.00 1.00 1.00 1.00 1.00 1.00 1.00 1.00 1.00 1.00 1.00 1.00 1.00 1.00 1.00 1.00 1.00 1.00 1.00 1.00 1.00 1.00 1.00 1.00 1.00 1.00 1.00 1.00 1.00 1.00 1.00 1.00 1.00 1.00 1.00 1.00 1.00 1.00 1.00 1.00 1.00 1.00 1.00 1.00 1.00 1.00 1.00 1.00 1.00 1.00 1.00 1.00 1.00 1.00 1.00 1.00 1.00 1.00 1.00 1.00 1.00 1.00 1.00 1.00 1.00 1.00 1.00 1.00</beamAttenuationFactors>
				<commonCountingTime unit="seconds">3.00</commonCountingTime>
				<intensities unit="counts">16 15 17 15 12 10 25 14 13 23 16 15 22 19 11 12 6 12 19 11 4 12 8 2 2 11 6 5 6 11 5 3 9 7 5 5 8 7 5 5 6 4 8 6 4 14 7 8 11 9 12 7 1 9 2 2 8 6 5 8 6 5 3 7 5 10 11 5 7 2 2 3 5 3 5</intensities>
			</dataPoints>
		</scan>
		<scan appendNumber="0" mode="Continuous" scanAxis="Omega-2Theta" status="Completed">
			<header>
				<startTimeStamp>2011-04-25T15:55:54+02:00</startTimeStamp>
				<endTimeStamp>2011-04-25T16:00:04+02:00</endTimeStamp>
				<author>
					<name>Mesures</name>
				</author>
				<source>
					<applicationSoftware version="2.0e">X'Pert Data Collector</applicationSoftware>
					<instrumentControlSoftware version="1.5 ">XPERT-PRO</instrumentControlSoftware>
					<instrumentID>0000000098722659</instrumentID>
				</source>
			</header>
			<scanAxisCenter>
				<position axis="2Theta" unit="deg">76.0000</position>
				<position axis="Omega" unit="deg">18.1466</position>
			</scanAxisCenter>
			<reflection>
				<material>SrTiO3</material>
				<hkl>
					<h>0</h>
					<k>1</k>
					<l>3</l>
				</hkl>
			</reflection>
			<dataPoints>
				<positions axis="2Theta" unit="deg">
					<startPosition>73.0400</startPosition>
					<endPosition>78.9600</endPosition>
				</positions>
				<positions axis="Omega" unit="deg">
					<startPosition>16.6666</startPosition>
					<endPosition>19.6266</endPosition>
				</positions>
				<positions axis="Phi" unit="deg">
					<commonPosition>0.00</commonPosition>
				</positions>
				<positions axis="Psi" unit="deg">
					<commonPosition>-0.40</commonPosition>
				</positions>
				<positions axis="X" unit="mm">
					<commonPosition>2.37</commonPosition>
				</positions>
				<positions axis="Y" unit="mm">
					<commonPosition>-0.98</commonPosition>
				</positions>
				<positions axis="Z" unit="mm">
					<commonPosition>9.695</commonPosition>
				</positions>
				<beamAttenuationFactors>1.00 1.00 1.00 1.00 1.00 1.00 1.00 1.00 1.00 1.00 1.00 1.00 1.00 1.00 1.00 1.00 1.00 1.00 1.00 1.00 1.00 1.00 1.00 1.00 1.00 1.00 1.00 1.00 1.00 1.00 1.00 1.00 1.00 1.00 1.00 1.00 1.00 1.00 1.00 1.00 1.00 1.00 1.00 1.00 1.00 1.00 1.00 1.00 1.00 1.00 1.00 1.00 1.00 1.00 1.00 1.00 1.00 1.00 1.00 1.00 1.00 1.00 1.00 1.00 1.00 1.00 1.00 1.00 1.00 1.00 1.00 1.00 1.00 1.00 1.00</beamAttenuationFactors>
				<commonCountingTime unit="seconds">3.00</commonCountingTime>
				<intensities unit="counts">11 18 22 19 13 14 22 11 16 16 22 18 18 20 21 21 20 8 15 14 14 7 9 13 14 6 10 8 8 7 3 5 8 9 8 10 6 8 5 6 7 7 8 6 9 5 10 8 11 10 4 8 11 4 5 6 9 5 4 6 5 3 11 12 8 10 3 7 6 6 3 7 4 5 5</intensities>
			</dataPoints>
		</scan>
		<scan appendNumber="0" mode="Continuous" scanAxis="Omega-2Theta" status="Completed">
			<header>
				<startTimeStamp>2011-04-25T16:00:16+02:00</startTimeStamp>
				<endTimeStamp>2011-04-25T16:04:26+02:00</endTimeStamp>
				<author>
					<name>Mesures</name>
				</author>
				<source>
					<applicationSoftware version="2.0e">X'Pert Data Collector</applicationSoftware>
					<instrumentControlSoftware version="1.5 ">XPERT-PRO</instrumentControlSoftware>
					<instrumentID>0000000098722659</instrumentID>
				</source>
			</header>
			<scanAxisCenter>
				<position axis="2Theta" unit="deg">76.0000</position>
				<position axis="Omega" unit="deg">18.1866</position>
			</scanAxisCenter>
			<reflection>
				<material>SrTiO3</material>
				<hkl>
					<h>0</h>
					<k>1</k>
					<l>3</l>
				</hkl>
			</reflection>
			<dataPoints>
				<positions axis="2Theta" unit="deg">
					<startPosition>73.0400</startPosition>
					<endPosition>78.9600</endPosition>
				</positions>
				<positions axis="Omega" unit="deg">
					<startPosition>16.7066</startPosition>
					<endPosition>19.6666</endPosition>
				</positions>
				<positions axis="Phi" unit="deg">
					<commonPosition>0.00</commonPosition>
				</positions>
				<positions axis="Psi" unit="deg">
					<commonPosition>-0.40</commonPosition>
				</positions>
				<positions axis="X" unit="mm">
					<commonPosition>2.37</commonPosition>
				</positions>
				<positions axis="Y" unit="mm">
					<commonPosition>-0.98</commonPosition>
				</positions>
				<positions axis="Z" unit="mm">
					<commonPosition>9.695</commonPosition>
				</positions>
				<beamAttenuationFactors>1.00 1.00 1.00 1.00 1.00 1.00 1.00 1.00 1.00 1.00 1.00 1.00 1.00 1.00 1.00 1.00 1.00 1.00 1.00 1.00 1.00 1.00 1.00 1.00 1.00 1.00 1.00 1.00 1.00 1.00 1.00 1.00 1.00 1.00 1.00 1.00 1.00 1.00 1.00 1.00 1.00 1.00 1.00 1.00 1.00 1.00 1.00 1.00 1.00 1.00 1.00 1.00 1.00 1.00 1.00 1.00 1.00 1.00 1.00 1.00 1.00 1.00 1.00 1.00 1.00 1.00 1.00 1.00 1.00 1.00 1.00 1.00 1.00 1.00 1.00</beamAttenuationFactors>
				<commonCountingTime unit="seconds">3.00</commonCountingTime>
				<intensities unit="counts">17 20 17 13 20 20 20 20 20 28 25 20 21 23 24 12 12 12 13 9 7 6 8 7 7 7 5 8 6 8 7 13 11 5 7 5 5 3 5 0 6 3 10 9 6 5 4 11 7 5 6 7 7 7 7 5 5 2 5 6 1 5 6 7 5 3 10 5 1 6 6 6 5 2 3</intensities>
			</dataPoints>
		</scan>
		<scan appendNumber="0" mode="Continuous" scanAxis="Omega-2Theta" status="Completed">
			<header>
				<startTimeStamp>2011-04-25T16:04:40+02:00</startTimeStamp>
				<endTimeStamp>2011-04-25T16:08:53+02:00</endTimeStamp>
				<author>
					<name>Mesures</name>
				</author>
				<source>
					<applicationSoftware version="2.0e">X'Pert Data Collector</applicationSoftware>
					<instrumentControlSoftware version="1.5 ">XPERT-PRO</instrumentControlSoftware>
					<instrumentID>0000000098722659</instrumentID>
				</source>
			</header>
			<scanAxisCenter>
				<position axis="2Theta" unit="deg">76.0000</position>
				<position axis="Omega" unit="deg">18.2266</position>
			</scanAxisCenter>
			<reflection>
				<material>SrTiO3</material>
				<hkl>
					<h>0</h>
					<k>1</k>
					<l>3</l>
				</hkl>
			</reflection>
			<dataPoints>
				<positions axis="2Theta" unit="deg">
					<startPosition>73.0400</startPosition>
					<endPosition>78.9600</endPosition>
				</positions>
				<positions axis="Omega" unit="deg">
					<startPosition>16.7466</startPosition>
					<endPosition>19.7066</endPosition>
				</positions>
				<positions axis="Phi" unit="deg">
					<commonPosition>0.00</commonPosition>
				</positions>
				<positions axis="Psi" unit="deg">
					<commonPosition>-0.40</commonPosition>
				</positions>
				<positions axis="X" unit="mm">
					<commonPosition>2.37</commonPosition>
				</positions>
				<positions axis="Y" unit="mm">
					<commonPosition>-0.98</commonPosition>
				</positions>
				<positions axis="Z" unit="mm">
					<commonPosition>9.695</commonPosition>
				</positions>
				<beamAttenuationFactors>1.00 1.00 1.00 1.00 1.00 1.00 1.00 1.00 1.00 1.00 1.00 1.00 1.00 1.00 1.00 1.00 1.00 1.00 1.00 1.00 1.00 1.00 1.00 1.00 1.00 1.00 1.00 1.00 1.00 1.00 1.00 1.00 1.00 1.00 1.00 1.00 1.00 1.00 1.00 1.00 1.00 1.00 1.00 1.00 1.00 1.00 1.00 1.00 1.00 1.00 1.00 1.00 1.00 1.00 1.00 1.00 1.00 1.00 1.00 1.00 1.00 1.00 1.00 1.00 1.00 1.00 1.00 1.00 1.00 1.00 1.00 1.00 1.00 1.00 1.00</beamAttenuationFactors>
				<commonCountingTime unit="seconds">3.00</commonCountingTime>
				<intensities unit="counts">26 26 20 22 28 23 21 27 26 25 26 25 26 24 20 18 26 26 16 16 12 15 10 10 5 11 7 10 2 13 12 15 6 4 4 9 7 5 7 8 6 11 10 12 13 7 2 7 3 9 5 12 6 2 2 5 4 9 4 5 2 10 7 8 9 5 3 13 13 4 5 6 0 4 8</intensities>
			</dataPoints>
		</scan>
		<scan appendNumber="0" mode="Continuous" scanAxis="Omega-2Theta" status="Completed">
			<header>
				<startTimeStamp>2011-04-25T16:09:07+02:00</startTimeStamp>
				<endTimeStamp>2011-04-25T16:13:18+02:00</endTimeStamp>
				<author>
					<name>Mesures</name>
				</author>
				<source>
					<applicationSoftware version="2.0e">X'Pert Data Collector</applicationSoftware>
					<instrumentControlSoftware version="1.5 ">XPERT-PRO</instrumentControlSoftware>
					<instrumentID>0000000098722659</instrumentID>
				</source>
			</header>
			<scanAxisCenter>
				<position axis="2Theta" unit="deg">76.0000</position>
				<position axis="Omega" unit="deg">18.2666</position>
			</scanAxisCenter>
			<reflection>
				<material>SrTiO3</material>
				<hkl>
					<h>0</h>
					<k>1</k>
					<l>3</l>
				</hkl>
			</reflection>
			<dataPoints>
				<positions axis="2Theta" unit="deg">
					<startPosition>73.0400</startPosition>
					<endPosition>78.9600</endPosition>
				</positions>
				<positions axis="Omega" unit="deg">
					<startPosition>16.7866</startPosition>
					<endPosition>19.7466</endPosition>
				</positions>
				<positions axis="Phi" unit="deg">
					<commonPosition>0.00</commonPosition>
				</positions>
				<positions axis="Psi" unit="deg">
					<commonPosition>-0.40</commonPosition>
				</positions>
				<positions axis="X" unit="mm">
					<commonPosition>2.37</commonPosition>
				</positions>
				<positions axis="Y" unit="mm">
					<commonPosition>-0.98</commonPosition>
				</positions>
				<positions axis="Z" unit="mm">
					<commonPosition>9.695</commonPosition>
				</positions>
				<beamAttenuationFactors>1.00 1.00 1.00 1.00 1.00 1.00 1.00 1.00 1.00 1.00 1.00 1.00 1.00 1.00 1.00 1.00 1.00 1.00 1.00 1.00 1.00 1.00 1.00 1.00 1.00 1.00 1.00 1.00 1.00 1.00 1.00 1.00 1.00 1.00 1.00 1.00 1.00 1.00 1.00 1.00 1.00 1.00 1.00 1.00 1.00 1.00 1.00 1.00 1.00 1.00 1.00 1.00 1.00 1.00 1.00 1.00 1.00 1.00 1.00 1.00 1.00 1.00 1.00 1.00 1.00 1.00 1.00 1.00 1.00 1.00 1.00 1.00 1.00 1.00 1.00</beamAttenuationFactors>
				<commonCountingTime unit="seconds">3.00</commonCountingTime>
				<intensities unit="counts">19 17 22 28 34 27 30 33 22 25 29 33 38 35 31 22 21 25 18 18 18 14 8 4 7 7 13 10 6 10 4 7 5 11 14 8 6 10 8 9 8 12 9 5 8 8 5 13 9 5 10 7 6 10 12 11 11 9 4 4 13 3 7 6 5 5 3 3 7 2 6 3 4 11 6</intensities>
			</dataPoints>
		</scan>
		<scan appendNumber="0" mode="Continuous" scanAxis="Omega-2Theta" status="Completed">
			<header>
				<startTimeStamp>2011-04-25T16:13:35+02:00</startTimeStamp>
				<endTimeStamp>2011-04-25T16:17:43+02:00</endTimeStamp>
				<author>
					<name>Mesures</name>
				</author>
				<source>
					<applicationSoftware version="2.0e">X'Pert Data Collector</applicationSoftware>
					<instrumentControlSoftware version="1.5 ">XPERT-PRO</instrumentControlSoftware>
					<instrumentID>0000000098722659</instrumentID>
				</source>
			</header>
			<scanAxisCenter>
				<position axis="2Theta" unit="deg">76.0000</position>
				<position axis="Omega" unit="deg">18.3066</position>
			</scanAxisCenter>
			<reflection>
				<material>SrTiO3</material>
				<hkl>
					<h>0</h>
					<k>1</k>
					<l>3</l>
				</hkl>
			</reflection>
			<dataPoints>
				<positions axis="2Theta" unit="deg">
					<startPosition>73.0400</startPosition>
					<endPosition>78.9600</endPosition>
				</positions>
				<positions axis="Omega" unit="deg">
					<startPosition>16.8266</startPosition>
					<endPosition>19.7866</endPosition>
				</positions>
				<positions axis="Phi" unit="deg">
					<commonPosition>0.00</commonPosition>
				</positions>
				<positions axis="Psi" unit="deg">
					<commonPosition>-0.40</commonPosition>
				</positions>
				<positions axis="X" unit="mm">
					<commonPosition>2.37</commonPosition>
				</positions>
				<positions axis="Y" unit="mm">
					<commonPosition>-0.98</commonPosition>
				</positions>
				<positions axis="Z" unit="mm">
					<commonPosition>9.695</commonPosition>
				</positions>
				<beamAttenuationFactors>1.00 1.00 1.00 1.00 1.00 1.00 1.00 1.00 1.00 1.00 1.00 1.00 1.00 1.00 1.00 1.00 1.00 1.00 1.00 1.00 1.00 1.00 1.00 1.00 1.00 1.00 1.00 1.00 1.00 1.00 1.00 1.00 1.00 1.00 1.00 1.00 1.00 1.00 1.00 1.00 1.00 1.00 1.00 1.00 1.00 1.00 1.00 1.00 1.00 1.00 1.00 1.00 1.00 1.00 1.00 1.00 1.00 1.00 1.00 1.00 1.00 1.00 1.00 1.00 1.00 1.00 1.00 1.00 1.00 1.00 1.00 1.00 1.00 1.00 1.00</beamAttenuationFactors>
				<commonCountingTime unit="seconds">3.00</commonCountingTime>
				<intensities unit="counts">28 26 21 26 31 32 30 32 29 36 44 48 44 32 40 31 24 23 22 14 20 10 10 7 9 12 5 5 5 5 9 11 10 5 6 6 7 6 11 5 5 2 9 12 9 5 7 10 13 6 12 10 5 14 14 5 11 10 3 9 7 6 7 8 3 3 3 4 3 7 7 3 5 3 7</intensities>
			</dataPoints>
		</scan>
		<scan appendNumber="0" mode="Continuous" scanAxis="Omega-2Theta" status="Completed">
			<header>
				<startTimeStamp>2011-04-25T16:17:58+02:00</startTimeStamp>
				<endTimeStamp>2011-04-25T16:22:09+02:00</endTimeStamp>
				<author>
					<name>Mesures</name>
				</author>
				<source>
					<applicationSoftware version="2.0e">X'Pert Data Collector</applicationSoftware>
					<instrumentControlSoftware version="1.5 ">XPERT-PRO</instrumentControlSoftware>
					<instrumentID>0000000098722659</instrumentID>
				</source>
			</header>
			<scanAxisCenter>
				<position axis="2Theta" unit="deg">76.0000</position>
				<position axis="Omega" unit="deg">18.3466</position>
			</scanAxisCenter>
			<reflection>
				<material>SrTiO3</material>
				<hkl>
					<h>0</h>
					<k>1</k>
					<l>3</l>
				</hkl>
			</reflection>
			<dataPoints>
				<positions axis="2Theta" unit="deg">
					<startPosition>73.0400</startPosition>
					<endPosition>78.9600</endPosition>
				</positions>
				<positions axis="Omega" unit="deg">
					<startPosition>16.8666</startPosition>
					<endPosition>19.8266</endPosition>
				</positions>
				<positions axis="Phi" unit="deg">
					<commonPosition>0.00</commonPosition>
				</positions>
				<positions axis="Psi" unit="deg">
					<commonPosition>-0.40</commonPosition>
				</positions>
				<positions axis="X" unit="mm">
					<commonPosition>2.37</commonPosition>
				</positions>
				<positions axis="Y" unit="mm">
					<commonPosition>-0.98</commonPosition>
				</positions>
				<positions axis="Z" unit="mm">
					<commonPosition>9.695</commonPosition>
				</positions>
				<beamAttenuationFactors>1.00 1.00 1.00 1.00 1.00 1.00 1.00 1.00 1.00 1.00 1.00 1.00 1.00 1.00 1.00 1.00 1.00 1.00 1.00 1.00 1.00 1.00 1.00 1.00 1.00 1.00 1.00 1.00 1.00 1.00 1.00 1.00 1.00 1.00 1.00 1.00 1.00 1.00 1.00 1.00 1.00 1.00 1.00 1.00 1.00 1.00 1.00 1.00 1.00 1.00 1.00 1.00 1.00 1.00 1.00 1.00 1.00 1.00 1.00 1.00 1.00 1.00 1.00 1.00 1.00 1.00 1.00 1.00 1.00 1.00 1.00 1.00 1.00 1.00 1.00</beamAttenuationFactors>
				<commonCountingTime unit="seconds">3.00</commonCountingTime>
				<intensities unit="counts">22 24 34 44 39 38 37 45 38 43 56 48 53 41 29 36 28 22 21 20 20 9 20 6 10 9 5 15 8 13 6 7 6 6 7 7 4 7 7 8 9 5 5 5 3 10 8 7 16 13 15 11 10 2 10 7 6 7 4 5 7 7 8 10 4 10 5 5 12 0 6 4 5 9 5</intensities>
			</dataPoints>
		</scan>
		<scan appendNumber="0" mode="Continuous" scanAxis="Omega-2Theta" status="Completed">
			<header>
				<startTimeStamp>2011-04-25T16:22:24+02:00</startTimeStamp>
				<endTimeStamp>2011-04-25T16:26:33+02:00</endTimeStamp>
				<author>
					<name>Mesures</name>
				</author>
				<source>
					<applicationSoftware version="2.0e">X'Pert Data Collector</applicationSoftware>
					<instrumentControlSoftware version="1.5 ">XPERT-PRO</instrumentControlSoftware>
					<instrumentID>0000000098722659</instrumentID>
				</source>
			</header>
			<scanAxisCenter>
				<position axis="2Theta" unit="deg">76.0000</position>
				<position axis="Omega" unit="deg">18.3866</position>
			</scanAxisCenter>
			<reflection>
				<material>SrTiO3</material>
				<hkl>
					<h>0</h>
					<k>1</k>
					<l>3</l>
				</hkl>
			</reflection>
			<dataPoints>
				<positions axis="2Theta" unit="deg">
					<startPosition>73.0400</startPosition>
					<endPosition>78.9600</endPosition>
				</positions>
				<positions axis="Omega" unit="deg">
					<startPosition>16.9066</startPosition>
					<endPosition>19.8666</endPosition>
				</positions>
				<positions axis="Phi" unit="deg">
					<commonPosition>0.00</commonPosition>
				</positions>
				<positions axis="Psi" unit="deg">
					<commonPosition>-0.40</commonPosition>
				</positions>
				<positions axis="X" unit="mm">
					<commonPosition>2.37</commonPosition>
				</positions>
				<positions axis="Y" unit="mm">
					<commonPosition>-0.98</commonPosition>
				</positions>
				<positions axis="Z" unit="mm">
					<commonPosition>9.695</commonPosition>
				</positions>
				<beamAttenuationFactors>1.00 1.00 1.00 1.00 1.00 1.00 1.00 1.00 1.00 1.00 1.00 1.00 1.00 1.00 1.00 1.00 1.00 1.00 1.00 1.00 1.00 1.00 1.00 1.00 1.00 1.00 1.00 1.00 1.00 1.00 1.00 1.00 1.00 1.00 1.00 1.00 1.00 1.00 1.00 1.00 1.00 1.00 1.00 1.00 1.00 1.00 1.00 1.00 1.00 1.00 1.00 1.00 1.00 1.00 1.00 1.00 1.00 1.00 1.00 1.00 1.00 1.00 1.00 1.00 1.00 1.00 1.00 1.00 1.00 1.00 1.00 1.00 1.00 1.00 1.00</beamAttenuationFactors>
				<commonCountingTime unit="seconds">3.00</commonCountingTime>
				<intensities unit="counts">32 24 39 40 55 39 50 33 49 66 74 81 71 56 46 40 40 31 28 18 15 11 14 9 12 7 7 9 11 6 9 11 10 11 8 4 5 12 6 7 6 9 6 4 3 9 9 9 12 11 7 8 6 9 6 9 6 6 12 9 3 6 8 6 5 6 3 7 6 0 4 6 7 1 8</intensities>
			</dataPoints>
		</scan>
		<scan appendNumber="0" mode="Continuous" scanAxis="Omega-2Theta" status="Completed">
			<header>
				<startTimeStamp>2011-04-25T16:26:45+02:00</startTimeStamp>
				<endTimeStamp>2011-04-25T16:30:55+02:00</endTimeStamp>
				<author>
					<name>Mesures</name>
				</author>
				<source>
					<applicationSoftware version="2.0e">X'Pert Data Collector</applicationSoftware>
					<instrumentControlSoftware version="1.5 ">XPERT-PRO</instrumentControlSoftware>
					<instrumentID>0000000098722659</instrumentID>
				</source>
			</header>
			<scanAxisCenter>
				<position axis="2Theta" unit="deg">76.0000</position>
				<position axis="Omega" unit="deg">18.4266</position>
			</scanAxisCenter>
			<reflection>
				<material>SrTiO3</material>
				<hkl>
					<h>0</h>
					<k>1</k>
					<l>3</l>
				</hkl>
			</reflection>
			<dataPoints>
				<positions axis="2Theta" unit="deg">
					<startPosition>73.0400</startPosition>
					<endPosition>78.9600</endPosition>
				</positions>
				<positions axis="Omega" unit="deg">
					<startPosition>16.9466</startPosition>
					<endPosition>19.9066</endPosition>
				</positions>
				<positions axis="Phi" unit="deg">
					<commonPosition>0.00</commonPosition>
				</positions>
				<positions axis="Psi" unit="deg">
					<commonPosition>-0.40</commonPosition>
				</positions>
				<positions axis="X" unit="mm">
					<commonPosition>2.37</commonPosition>
				</positions>
				<positions axis="Y" unit="mm">
					<commonPosition>-0.98</commonPosition>
				</positions>
				<positions axis="Z" unit="mm">
					<commonPosition>9.695</commonPosition>
				</positions>
				<beamAttenuationFactors>1.00 1.00 1.00 1.00 1.00 1.00 1.00 1.00 1.00 1.00 1.00 1.00 1.00 1.00 1.00 1.00 1.00 1.00 1.00 1.00 1.00 1.00 1.00 1.00 1.00 1.00 1.00 1.00 1.00 1.00 1.00 1.00 1.00 1.00 1.00 1.00 1.00 1.00 1.00 1.00 1.00 1.00 1.00 1.00 1.00 1.00 1.00 1.00 1.00 1.00 1.00 1.00 1.00 1.00 1.00 1.00 1.00 1.00 1.00 1.00 1.00 1.00 1.00 1.00 1.00 1.00 1.00 1.00 1.00 1.00 1.00 1.00 1.00 1.00 1.00</beamAttenuationFactors>
				<commonCountingTime unit="seconds">3.00</commonCountingTime>
				<intensities unit="counts">45 39 43 49 43 53 52 67 57 54 71 68 63 58 43 43 50 35 22 24 21 14 23 10 11 16 14 8 7 7 4 7 6 6 4 7 9 5 7 2 10 7 8 9 5 4 5 9 15 7 6 10 8 9 5 12 4 6 10 8 5 8 10 6 5 8 15 6 8 2 8 5 6 7 6</intensities>
			</dataPoints>
		</scan>
		<scan appendNumber="0" mode="Continuous" scanAxis="Omega-2Theta" status="Completed">
			<header>
				<startTimeStamp>2011-04-25T16:31:06+02:00</startTimeStamp>
				<endTimeStamp>2011-04-25T16:35:16+02:00</endTimeStamp>
				<author>
					<name>Mesures</name>
				</author>
				<source>
					<applicationSoftware version="2.0e">X'Pert Data Collector</applicationSoftware>
					<instrumentControlSoftware version="1.5 ">XPERT-PRO</instrumentControlSoftware>
					<instrumentID>0000000098722659</instrumentID>
				</source>
			</header>
			<scanAxisCenter>
				<position axis="2Theta" unit="deg">76.0000</position>
				<position axis="Omega" unit="deg">18.4666</position>
			</scanAxisCenter>
			<reflection>
				<material>SrTiO3</material>
				<hkl>
					<h>0</h>
					<k>1</k>
					<l>3</l>
				</hkl>
			</reflection>
			<dataPoints>
				<positions axis="2Theta" unit="deg">
					<startPosition>73.0400</startPosition>
					<endPosition>78.9600</endPosition>
				</positions>
				<positions axis="Omega" unit="deg">
					<startPosition>16.9866</startPosition>
					<endPosition>19.9466</endPosition>
				</positions>
				<positions axis="Phi" unit="deg">
					<commonPosition>0.00</commonPosition>
				</positions>
				<positions axis="Psi" unit="deg">
					<commonPosition>-0.40</commonPosition>
				</positions>
				<positions axis="X" unit="mm">
					<commonPosition>2.37</commonPosition>
				</positions>
				<positions axis="Y" unit="mm">
					<commonPosition>-0.98</commonPosition>
				</positions>
				<positions axis="Z" unit="mm">
					<commonPosition>9.695</commonPosition>
				</positions>
				<beamAttenuationFactors>1.00 1.00 1.00 1.00 1.00 1.00 1.00 1.00 1.00 1.00 1.00 1.00 1.00 1.00 1.00 1.00 1.00 1.00 1.00 1.00 1.00 1.00 1.00 1.00 1.00 1.00 1.00 1.00 1.00 1.00 1.00 1.00 1.00 1.00 1.00 1.00 1.00 1.00 1.00 1.00 1.00 1.00 1.00 1.00 1.00 1.00 1.00 1.00 1.00 1.00 1.00 1.00 1.00 1.00 1.00 1.00 1.00 1.00 1.00 1.00 1.00 1.00 1.00 1.00 1.00 1.00 1.00 1.00 1.00 1.00 1.00 1.00 1.00 1.00 1.00</beamAttenuationFactors>
				<commonCountingTime unit="seconds">3.00</commonCountingTime>
				<intensities unit="counts">28 43 47 56 52 73 71 73 84 78 80 80 88 78 60 39 50 27 23 28 25 6 13 16 14 11 13 18 8 8 14 10 8 6 11 3 5 5 5 10 7 9 8 7 2 6 8 12 11 7 9 11 9 11 10 10 8 8 6 6 5 7 7 7 11 8 3 3 7 4 3 3 4 5 3</intensities>
			</dataPoints>
		</scan>
		<scan appendNumber="0" mode="Continuous" scanAxis="Omega-2Theta" status="Completed">
			<header>
				<startTimeStamp>2011-04-25T16:35:28+02:00</startTimeStamp>
				<endTimeStamp>2011-04-25T16:39:39+02:00</endTimeStamp>
				<author>
					<name>Mesures</name>
				</author>
				<source>
					<applicationSoftware version="2.0e">X'Pert Data Collector</applicationSoftware>
					<instrumentControlSoftware version="1.5 ">XPERT-PRO</instrumentControlSoftware>
					<instrumentID>0000000098722659</instrumentID>
				</source>
			</header>
			<scanAxisCenter>
				<position axis="2Theta" unit="deg">76.0000</position>
				<position axis="Omega" unit="deg">18.5066</position>
			</scanAxisCenter>
			<reflection>
				<material>SrTiO3</material>
				<hkl>
					<h>0</h>
					<k>1</k>
					<l>3</l>
				</hkl>
			</reflection>
			<dataPoints>
				<positions axis="2Theta" unit="deg">
					<startPosition>73.0400</startPosition>
					<endPosition>78.9600</endPosition>
				</positions>
				<positions axis="Omega" unit="deg">
					<startPosition>17.0266</startPosition>
					<endPosition>19.9866</endPosition>
				</positions>
				<positions axis="Phi" unit="deg">
					<commonPosition>0.00</commonPosition>
				</positions>
				<positions axis="Psi" unit="deg">
					<commonPosition>-0.40</commonPosition>
				</positions>
				<positions axis="X" unit="mm">
					<commonPosition>2.37</commonPosition>
				</positions>
				<positions axis="Y" unit="mm">
					<commonPosition>-0.98</commonPosition>
				</positions>
				<positions axis="Z" unit="mm">
					<commonPosition>9.695</commonPosition>
				</positions>
				<beamAttenuationFactors>1.00 1.00 1.00 1.00 1.00 1.00 1.00 1.00 1.00 1.00 1.00 1.00 1.00 1.00 1.00 1.00 1.00 1.00 1.00 1.00 1.00 1.00 1.00 1.00 1.00 1.00 1.00 1.00 1.00 1.00 1.00 1.00 1.00 1.00 1.00 1.00 1.00 1.00 1.00 1.00 1.00 1.00 1.00 1.00 1.00 1.00 1.00 1.00 1.00 1.00 1.00 1.00 1.00 1.00 1.00 1.00 1.00 1.00 1.00 1.00 1.00 1.00 1.00 1.00 1.00 1.00 1.00 1.00 1.00 1.00 1.00 1.00 1.00 1.00 1.00</beamAttenuationFactors>
				<commonCountingTime unit="seconds">3.00</commonCountingTime>
				<intensities unit="counts">46 48 57 64 73 70 63 85 84 109 101 112 96 90 71 65 39 46 30 26 20 11 17 6 14 8 7 3 6 13 8 12 6 10 5 14 9 7 6 2 5 7 9 6 5 7 9 10 10 8 9 10 13 9 5 12 12 10 3 7 10 4 10 6 5 8 7 5 0 4 1 7 3 7 6</intensities>
			</dataPoints>
		</scan>
		<scan appendNumber="0" mode="Continuous" scanAxis="Omega-2Theta" status="Completed">
			<header>
				<startTimeStamp>2011-04-25T16:39:52+02:00</startTimeStamp>
				<endTimeStamp>2011-04-25T16:43:58+02:00</endTimeStamp>
				<author>
					<name>Mesures</name>
				</author>
				<source>
					<applicationSoftware version="2.0e">X'Pert Data Collector</applicationSoftware>
					<instrumentControlSoftware version="1.5 ">XPERT-PRO</instrumentControlSoftware>
					<instrumentID>0000000098722659</instrumentID>
				</source>
			</header>
			<scanAxisCenter>
				<position axis="2Theta" unit="deg">76.0000</position>
				<position axis="Omega" unit="deg">18.5466</position>
			</scanAxisCenter>
			<reflection>
				<material>SrTiO3</material>
				<hkl>
					<h>0</h>
					<k>1</k>
					<l>3</l>
				</hkl>
			</reflection>
			<dataPoints>
				<positions axis="2Theta" unit="deg">
					<startPosition>73.0400</startPosition>
					<endPosition>78.9600</endPosition>
				</positions>
				<positions axis="Omega" unit="deg">
					<startPosition>17.0666</startPosition>
					<endPosition>20.0266</endPosition>
				</positions>
				<positions axis="Phi" unit="deg">
					<commonPosition>0.00</commonPosition>
				</positions>
				<positions axis="Psi" unit="deg">
					<commonPosition>-0.40</commonPosition>
				</positions>
				<positions axis="X" unit="mm">
					<commonPosition>2.37</commonPosition>
				</positions>
				<positions axis="Y" unit="mm">
					<commonPosition>-0.98</commonPosition>
				</positions>
				<positions axis="Z" unit="mm">
					<commonPosition>9.695</commonPosition>
				</positions>
				<beamAttenuationFactors>1.00 1.00 1.00 1.00 1.00 1.00 1.00 1.00 1.00 1.00 1.00 1.00 1.00 1.00 1.00 1.00 1.00 1.00 1.00 1.00 1.00 1.00 1.00 1.00 1.00 1.00 1.00 1.00 1.00 1.00 1.00 1.00 1.00 1.00 1.00 1.00 1.00 1.00 1.00 1.00 1.00 1.00 1.00 1.00 1.00 1.00 1.00 1.00 1.00 1.00 1.00 1.00 1.00 1.00 1.00 1.00 1.00 1.00 1.00 1.00 1.00 1.00 1.00 1.00 1.00 1.00 1.00 1.00 1.00 1.00 1.00 1.00 1.00 1.00 1.00</beamAttenuationFactors>
				<commonCountingTime unit="seconds">3.00</commonCountingTime>
				<intensities unit="counts">56 53 62 71 72 88 99 96 104 111 134 122 110 105 99 81 73 53 34 28 30 14 12 9 8 13 12 4 10 7 3 9 6 4 6 9 7 7 8 6 7 13 8 6 5 10 7 9 13 11 13 16 12 7 13 10 9 9 10 8 4 14 4 11 6 6 11 6 8 8 3 3 6 10 4</intensities>
			</dataPoints>
		</scan>
		<scan appendNumber="0" mode="Continuous" scanAxis="Omega-2Theta" status="Completed">
			<header>
				<startTimeStamp>2011-04-25T16:44:13+02:00</startTimeStamp>
				<endTimeStamp>2011-04-25T16:48:21+02:00</endTimeStamp>
				<author>
					<name>Mesures</name>
				</author>
				<source>
					<applicationSoftware version="2.0e">X'Pert Data Collector</applicationSoftware>
					<instrumentControlSoftware version="1.5 ">XPERT-PRO</instrumentControlSoftware>
					<instrumentID>0000000098722659</instrumentID>
				</source>
			</header>
			<scanAxisCenter>
				<position axis="2Theta" unit="deg">76.0000</position>
				<position axis="Omega" unit="deg">18.5866</position>
			</scanAxisCenter>
			<reflection>
				<material>SrTiO3</material>
				<hkl>
					<h>0</h>
					<k>1</k>
					<l>3</l>
				</hkl>
			</reflection>
			<dataPoints>
				<positions axis="2Theta" unit="deg">
					<startPosition>73.0400</startPosition>
					<endPosition>78.9600</endPosition>
				</positions>
				<positions axis="Omega" unit="deg">
					<startPosition>17.1066</startPosition>
					<endPosition>20.0666</endPosition>
				</positions>
				<positions axis="Phi" unit="deg">
					<commonPosition>0.00</commonPosition>
				</positions>
				<positions axis="Psi" unit="deg">
					<commonPosition>-0.40</commonPosition>
				</positions>
				<positions axis="X" unit="mm">
					<commonPosition>2.37</commonPosition>
				</positions>
				<positions axis="Y" unit="mm">
					<commonPosition>-0.98</commonPosition>
				</positions>
				<positions axis="Z" unit="mm">
					<commonPosition>9.695</commonPosition>
				</positions>
				<beamAttenuationFactors>1.00 1.00 1.00 1.00 1.00 1.00 1.00 1.00 1.00 1.00 1.00 1.00 1.00 1.00 1.00 1.00 1.00 1.00 1.00 1.00 1.00 1.00 1.00 1.00 1.00 1.00 1.00 1.00 1.00 1.00 1.00 1.00 1.00 1.00 1.00 1.00 1.00 1.00 1.00 1.00 1.00 1.00 1.00 1.00 1.00 1.00 1.00 1.00 1.00 1.00 1.00 1.00 1.00 1.00 1.00 1.00 1.00 1.00 1.00 1.00 1.00 1.00 1.00 1.00 1.00 1.00 1.00 1.00 1.00 1.00 1.00 1.00 1.00 1.00 1.00</beamAttenuationFactors>
				<commonCountingTime unit="seconds">3.00</commonCountingTime>
				<intensities unit="counts">47 60 57 82 108 100 102 116 130 133 128 138 136 108 111 90 69 59 47 37 24 21 24 14 12 10 11 13 9 7 7 5 7 8 4 6 5 9 6 7 9 11 11 7 5 4 10 11 14 12 12 9 11 11 11 12 4 5 6 5 8 10 7 9 8 10 7 7 4 6 6 11 6 6 7</intensities>
			</dataPoints>
		</scan>
		<scan appendNumber="0" mode="Continuous" scanAxis="Omega-2Theta" status="Completed">
			<header>
				<startTimeStamp>2011-04-25T16:48:33+02:00</startTimeStamp>
				<endTimeStamp>2011-04-25T16:52:44+02:00</endTimeStamp>
				<author>
					<name>Mesures</name>
				</author>
				<source>
					<applicationSoftware version="2.0e">X'Pert Data Collector</applicationSoftware>
					<instrumentControlSoftware version="1.5 ">XPERT-PRO</instrumentControlSoftware>
					<instrumentID>0000000098722659</instrumentID>
				</source>
			</header>
			<scanAxisCenter>
				<position axis="2Theta" unit="deg">76.0000</position>
				<position axis="Omega" unit="deg">18.6266</position>
			</scanAxisCenter>
			<reflection>
				<material>SrTiO3</material>
				<hkl>
					<h>0</h>
					<k>1</k>
					<l>3</l>
				</hkl>
			</reflection>
			<dataPoints>
				<positions axis="2Theta" unit="deg">
					<startPosition>73.0400</startPosition>
					<endPosition>78.9600</endPosition>
				</positions>
				<positions axis="Omega" unit="deg">
					<startPosition>17.1466</startPosition>
					<endPosition>20.1066</endPosition>
				</positions>
				<positions axis="Phi" unit="deg">
					<commonPosition>0.00</commonPosition>
				</positions>
				<positions axis="Psi" unit="deg">
					<commonPosition>-0.40</commonPosition>
				</positions>
				<positions axis="X" unit="mm">
					<commonPosition>2.37</commonPosition>
				</positions>
				<positions axis="Y" unit="mm">
					<commonPosition>-0.98</commonPosition>
				</positions>
				<positions axis="Z" unit="mm">
					<commonPosition>9.695</commonPosition>
				</positions>
				<beamAttenuationFactors>1.00 1.00 1.00 1.00 1.00 1.00 1.00 1.00 1.00 1.00 1.00 1.00 1.00 1.00 1.00 1.00 1.00 1.00 1.00 1.00 1.00 1.00 1.00 1.00 1.00 1.00 1.00 1.00 1.00 1.00 1.00 1.00 1.00 1.00 1.00 1.00 1.00 1.00 1.00 1.00 1.00 1.00 1.00 1.00 1.00 1.00 1.00 1.00 1.00 1.00 1.00 1.00 1.00 1.00 1.00 1.00 1.00 1.00 1.00 1.00 1.00 1.00 1.00 1.00 1.00 1.00 1.00 1.00 1.00 1.00 1.00 1.00 1.00 1.00 1.00</beamAttenuationFactors>
				<commonCountingTime unit="seconds">3.00</commonCountingTime>
				<intensities unit="counts">78 73 76 101 114 124 136 140 142 155 141 159 160 167 126 91 87 52 52 35 28 30 19 22 18 17 12 10 13 15 16 12 12 11 4 5 11 6 10 4 7 7 5 4 9 10 14 14 6 9 16 10 8 5 11 9 11 8 10 7 4 7 8 9 2 7 4 3 7 4 6 8 3 3 2</intensities>
			</dataPoints>
		</scan>
		<scan appendNumber="0" mode="Continuous" scanAxis="Omega-2Theta" status="Completed">
			<header>
				<startTimeStamp>2011-04-25T16:52:58+02:00</startTimeStamp>
				<endTimeStamp>2011-04-25T16:57:07+02:00</endTimeStamp>
				<author>
					<name>Mesures</name>
				</author>
				<source>
					<applicationSoftware version="2.0e">X'Pert Data Collector</applicationSoftware>
					<instrumentControlSoftware version="1.5 ">XPERT-PRO</instrumentControlSoftware>
					<instrumentID>0000000098722659</instrumentID>
				</source>
			</header>
			<scanAxisCenter>
				<position axis="2Theta" unit="deg">76.0000</position>
				<position axis="Omega" unit="deg">18.6666</position>
			</scanAxisCenter>
			<reflection>
				<material>SrTiO3</material>
				<hkl>
					<h>0</h>
					<k>1</k>
					<l>3</l>
				</hkl>
			</reflection>
			<dataPoints>
				<positions axis="2Theta" unit="deg">
					<startPosition>73.0400</startPosition>
					<endPosition>78.9600</endPosition>
				</positions>
				<positions axis="Omega" unit="deg">
					<startPosition>17.1866</startPosition>
					<endPosition>20.1466</endPosition>
				</positions>
				<positions axis="Phi" unit="deg">
					<commonPosition>0.00</commonPosition>
				</positions>
				<positions axis="Psi" unit="deg">
					<commonPosition>-0.40</commonPosition>
				</positions>
				<positions axis="X" unit="mm">
					<commonPosition>2.37</commonPosition>
				</positions>
				<positions axis="Y" unit="mm">
					<commonPosition>-0.98</commonPosition>
				</positions>
				<positions axis="Z" unit="mm">
					<commonPosition>9.695</commonPosition>
				</positions>
[...]
					<startPosition>19.2666</startPosition>
					<endPosition>22.2266</endPosition>
				</positions>
				<positions axis="Phi" unit="deg">
					<commonPosition>0.00</commonPosition>
				</positions>
				<positions axis="Psi" unit="deg">
					<commonPosition>-0.40</commonPosition>
				</positions>
				<positions axis="X" unit="mm">
					<commonPosition>2.37</commonPosition>
				</positions>
				<positions axis="Y" unit="mm">
					<commonPosition>-0.98</commonPosition>
				</positions>
				<positions axis="Z" unit="mm">
					<commonPosition>9.695</commonPosition>
				</positions>
				<beamAttenuationFactors>1.00 1.00 1.00 1.00 1.00 1.00 1.00 1.00 1.00 1.00 1.00 1.00 1.00 1.00 1.00 1.00 1.00 1.00 1.00 1.00 1.00 1.00 1.00 1.00 1.00 1.00 1.00 1.00 1.00 1.00 1.00 1.00 1.00 1.00 1.00 1.00 1.00 1.00 1.00 1.00 1.00 1.00 1.00 1.00 1.00 1.00 1.00 1.00 1.00 1.00 1.00 1.00 1.00 1.00 1.00 1.00 1.00 1.00 1.00 1.00 1.00 1.00 1.00 1.00 1.00 1.00 1.00 1.00 1.00 1.00 1.00 1.00 1.00 1.00 1.00</beamAttenuationFactors>
				<commonCountingTime unit="seconds">3.00</commonCountingTime>
				<intensities unit="counts">5 6 3 5 6 4 2 4 4 2 5 6 1 7 6 4 9 4 8 6 4 4 5 8 11 11 8 6 9 8 7 6 10 6 13 8 11 6 6 6 10 8 7 9 11 9 7 5 13 11 20 18 15 14 13 8 8 4 11 10 6 5 8 6 7 6 6 9 4 6 6 7 6 7 2</intensities>
			</dataPoints>
		</scan>
		<scan appendNumber="0" mode="Continuous" scanAxis="Omega-2Theta" status="Completed">
			<header>
				<startTimeStamp>2011-04-25T20:45:45+02:00</startTimeStamp>
				<endTimeStamp>2011-04-25T20:49:58+02:00</endTimeStamp>
				<author>
					<name>Mesures</name>
				</author>
				<source>
					<applicationSoftware version="2.0e">X'Pert Data Collector</applicationSoftware>
					<instrumentControlSoftware version="1.5 ">XPERT-PRO</instrumentControlSoftware>
					<instrumentID>0000000098722659</instrumentID>
				</source>
			</header>
			<scanAxisCenter>
				<position axis="2Theta" unit="deg">76.0000</position>
				<position axis="Omega" unit="deg">20.7866</position>
			</scanAxisCenter>
			<reflection>
				<material>SrTiO3</material>
				<hkl>
					<h>0</h>
					<k>1</k>
					<l>3</l>
				</hkl>
			</reflection>
			<dataPoints>
				<positions axis="2Theta" unit="deg">
					<startPosition>73.0400</startPosition>
					<endPosition>78.9600</endPosition>
				</positions>
				<positions axis="Omega" unit="deg">
					<startPosition>19.3066</startPosition>
					<endPosition>22.2666</endPosition>
				</positions>
				<positions axis="Phi" unit="deg">
					<commonPosition>0.00</commonPosition>
				</positions>
				<positions axis="Psi" unit="deg">
					<commonPosition>-0.40</commonPosition>
				</positions>
				<positions axis="X" unit="mm">
					<commonPosition>2.37</commonPosition>
				</positions>
				<positions axis="Y" unit="mm">
					<commonPosition>-0.98</commonPosition>
				</positions>
				<positions axis="Z" unit="mm">
					<commonPosition>9.695</commonPosition>
				</positions>
				<beamAttenuationFactors>1.00 1.00 1.00 1.00 1.00 1.00 1.00 1.00 1.00 1.00 1.00 1.00 1.00 1.00 1.00 1.00 1.00 1.00 1.00 1.00 1.00 1.00 1.00 1.00 1.00 1.00 1.00 1.00 1.00 1.00 1.00 1.00 1.00 1.00 1.00 1.00 1.00 1.00 1.00 1.00 1.00 1.00 1.00 1.00 1.00 1.00 1.00 1.00 1.00 1.00 1.00 1.00 1.00 1.00 1.00 1.00 1.00 1.00 1.00 1.00 1.00 1.00 1.00 1.00 1.00 1.00 1.00 1.00 1.00 1.00 1.00 1.00 1.00 1.00 1.00</beamAttenuationFactors>
				<commonCountingTime unit="seconds">3.00</commonCountingTime>
				<intensities unit="counts">3 4 4 5 5 5 3 3 7 8 8 4 3 11 4 5 2 4 6 5 1 6 7 4 10 10 10 6 8 7 4 3 2 6 9 2 12 8 4 6 7 5 7 7 6 8 3 8 13 9 26 14 20 12 6 7 6 7 5 7 4 5 8 9 4 2 8 8 5 5 5 9 6 3 5</intensities>
			</dataPoints>
		</scan>
		<scan appendNumber="0" mode="Continuous" scanAxis="Omega-2Theta" status="Completed">
			<header>
				<startTimeStamp>2011-04-25T20:50:12+02:00</startTimeStamp>
				<endTimeStamp>2011-04-25T20:54:24+02:00</endTimeStamp>
				<author>
					<name>Mesures</name>
				</author>
				<source>
					<applicationSoftware version="2.0e">X'Pert Data Collector</applicationSoftware>
					<instrumentControlSoftware version="1.5 ">XPERT-PRO</instrumentControlSoftware>
					<instrumentID>0000000098722659</instrumentID>
				</source>
			</header>
			<scanAxisCenter>
				<position axis="2Theta" unit="deg">76.0000</position>
				<position axis="Omega" unit="deg">20.8266</position>
			</scanAxisCenter>
			<reflection>
				<material>SrTiO3</material>
				<hkl>
					<h>0</h>
					<k>1</k>
					<l>3</l>
				</hkl>
			</reflection>
			<dataPoints>
				<positions axis="2Theta" unit="deg">
					<startPosition>73.0400</startPosition>
					<endPosition>78.9600</endPosition>
				</positions>
				<positions axis="Omega" unit="deg">
					<startPosition>19.3466</startPosition>
					<endPosition>22.3066</endPosition>
				</positions>
				<positions axis="Phi" unit="deg">
					<commonPosition>0.00</commonPosition>
				</positions>
				<positions axis="Psi" unit="deg">
					<commonPosition>-0.40</commonPosition>
				</positions>
				<positions axis="X" unit="mm">
					<commonPosition>2.37</commonPosition>
				</positions>
				<positions axis="Y" unit="mm">
					<commonPosition>-0.98</commonPosition>
				</positions>
				<positions axis="Z" unit="mm">
					<commonPosition>9.695</commonPosition>
				</positions>
				<beamAttenuationFactors>1.00 1.00 1.00 1.00 1.00 1.00 1.00 1.00 1.00 1.00 1.00 1.00 1.00 1.00 1.00 1.00 1.00 1.00 1.00 1.00 1.00 1.00 1.00 1.00 1.00 1.00 1.00 1.00 1.00 1.00 1.00 1.00 1.00 1.00 1.00 1.00 1.00 1.00 1.00 1.00 1.00 1.00 1.00 1.00 1.00 1.00 1.00 1.00 1.00 1.00 1.00 1.00 1.00 1.00 1.00 1.00 1.00 1.00 1.00 1.00 1.00 1.00 1.00 1.00 1.00 1.00 1.00 1.00 1.00 1.00 1.00 1.00 1.00 1.00 1.00</beamAttenuationFactors>
				<commonCountingTime unit="seconds">3.00</commonCountingTime>
				<intensities unit="counts">4 4 4 9 4 0 4 4 3 2 2 2 7 6 4 3 7 5 4 6 5 8 11 10 4 9 6 2 6 5 8 9 7 5 12 5 9 8 10 6 10 12 8 9 5 6 9 9 7 14 17 28 16 11 10 12 8 9 6 10 8 10 8 7 15 7 4 5 5 4 5 3 4 9 5</intensities>
			</dataPoints>
		</scan>
		<scan appendNumber="0" mode="Continuous" scanAxis="Omega-2Theta" status="Completed">
			<header>
				<startTimeStamp>2011-04-25T20:54:39+02:00</startTimeStamp>
				<endTimeStamp>2011-04-25T20:58:49+02:00</endTimeStamp>
				<author>
					<name>Mesures</name>
				</author>
				<source>
					<applicationSoftware version="2.0e">X'Pert Data Collector</applicationSoftware>
					<instrumentControlSoftware version="1.5 ">XPERT-PRO</instrumentControlSoftware>
					<instrumentID>0000000098722659</instrumentID>
				</source>
			</header>
			<scanAxisCenter>
				<position axis="2Theta" unit="deg">76.0000</position>
				<position axis="Omega" unit="deg">20.8666</position>
			</scanAxisCenter>
			<reflection>
				<material>SrTiO3</material>
				<hkl>
					<h>0</h>
					<k>1</k>
					<l>3</l>
				</hkl>
			</reflection>
			<dataPoints>
				<positions axis="2Theta" unit="deg">
					<startPosition>73.0400</startPosition>
					<endPosition>78.9600</endPosition>
				</positions>
				<positions axis="Omega" unit="deg">
					<startPosition>19.3866</startPosition>
					<endPosition>22.3466</endPosition>
				</positions>
				<positions axis="Phi" unit="deg">
					<commonPosition>0.00</commonPosition>
				</positions>
				<positions axis="Psi" unit="deg">
					<commonPosition>-0.40</commonPosition>
				</positions>
				<positions axis="X" unit="mm">
					<commonPosition>2.37</commonPosition>
				</positions>
				<positions axis="Y" unit="mm">
					<commonPosition>-0.98</commonPosition>
				</positions>
				<positions axis="Z" unit="mm">
					<commonPosition>9.695</commonPosition>
				</positions>
				<beamAttenuationFactors>1.00 1.00 1.00 1.00 1.00 1.00 1.00 1.00 1.00 1.00 1.00 1.00 1.00 1.00 1.00 1.00 1.00 1.00 1.00 1.00 1.00 1.00 1.00 1.00 1.00 1.00 1.00 1.00 1.00 1.00 1.00 1.00 1.00 1.00 1.00 1.00 1.00 1.00 1.00 1.00 1.00 1.00 1.00 1.00 1.00 1.00 1.00 1.00 1.00 1.00 1.00 1.00 1.00 1.00 1.00 1.00 1.00 1.00 1.00 1.00 1.00 1.00 1.00 1.00 1.00 1.00 1.00 1.00 1.00 1.00 1.00 1.00 1.00 1.00 1.00</beamAttenuationFactors>
				<commonCountingTime unit="seconds">3.00</commonCountingTime>
				<intensities unit="counts">1 7 3 7 6 2 5 4 0 3 6 4 3 2 6 8 2 5 4 4 8 5 7 9 3 6 7 4 5 4 9 6 6 3 13 3 9 10 8 7 6 8 11 3 6 8 5 8 3 13 12 22 16 14 13 3 5 10 13 1 3 2 8 5 5 7 4 2 3 3 7 5 7 5 8</intensities>
			</dataPoints>
		</scan>
		<scan appendNumber="0" mode="Continuous" scanAxis="Omega-2Theta" status="Completed">
			<header>
				<startTimeStamp>2011-04-25T20:59:02+02:00</startTimeStamp>
				<endTimeStamp>2011-04-25T21:03:11+02:00</endTimeStamp>
				<author>
					<name>Mesures</name>
				</author>
				<source>
					<applicationSoftware version="2.0e">X'Pert Data Collector</applicationSoftware>
					<instrumentControlSoftware version="1.5 ">XPERT-PRO</instrumentControlSoftware>
					<instrumentID>0000000098722659</instrumentID>
				</source>
			</header>
			<scanAxisCenter>
				<position axis="2Theta" unit="deg">76.0000</position>
				<position axis="Omega" unit="deg">20.9066</position>
			</scanAxisCenter>
			<reflection>
				<material>SrTiO3</material>
				<hkl>
					<h>0</h>
					<k>1</k>
					<l>3</l>
				</hkl>
			</reflection>
			<dataPoints>
				<positions axis="2Theta" unit="deg">
					<startPosition>73.0400</startPosition>
					<endPosition>78.9600</endPosition>
				</positions>
				<positions axis="Omega" unit="deg">
					<startPosition>19.4266</startPosition>
					<endPosition>22.3866</endPosition>
				</positions>
				<positions axis="Phi" unit="deg">
					<commonPosition>0.00</commonPosition>
				</positions>
				<positions axis="Psi" unit="deg">
					<commonPosition>-0.40</commonPosition>
				</positions>
				<positions axis="X" unit="mm">
					<commonPosition>2.37</commonPosition>
				</positions>
				<positions axis="Y" unit="mm">
					<commonPosition>-0.98</commonPosition>
				</positions>
				<positions axis="Z" unit="mm">
					<commonPosition>9.695</commonPosition>
				</positions>
				<beamAttenuationFactors>1.00 1.00 1.00 1.00 1.00 1.00 1.00 1.00 1.00 1.00 1.00 1.00 1.00 1.00 1.00 1.00 1.00 1.00 1.00 1.00 1.00 1.00 1.00 1.00 1.00 1.00 1.00 1.00 1.00 1.00 1.00 1.00 1.00 1.00 1.00 1.00 1.00 1.00 1.00 1.00 1.00 1.00 1.00 1.00 1.00 1.00 1.00 1.00 1.00 1.00 1.00 1.00 1.00 1.00 1.00 1.00 1.00 1.00 1.00 1.00 1.00 1.00 1.00 1.00 1.00 1.00 1.00 1.00 1.00 1.00 1.00 1.00 1.00 1.00 1.00</beamAttenuationFactors>
				<commonCountingTime unit="seconds">3.00</commonCountingTime>
				<intensities unit="counts">3 8 5 3 6 3 10 2 2 3 8 3 6 4 9 4 5 5 4 12 5 4 4 11 3 7 12 4 5 1 3 6 4 9 6 6 6 8 4 8 7 6 6 6 4 11 5 12 6 14 11 25 19 11 5 3 3 8 6 10 5 4 8 5 8 8 6 4 8 2 8 5 7 4 7</intensities>
			</dataPoints>
		</scan>
		<scan appendNumber="0" mode="Continuous" scanAxis="Omega-2Theta" status="Completed">
			<header>
				<startTimeStamp>2011-04-25T21:03:26+02:00</startTimeStamp>
				<endTimeStamp>2011-04-25T21:07:36+02:00</endTimeStamp>
				<author>
					<name>Mesures</name>
				</author>
				<source>
					<applicationSoftware version="2.0e">X'Pert Data Collector</applicationSoftware>
					<instrumentControlSoftware version="1.5 ">XPERT-PRO</instrumentControlSoftware>
					<instrumentID>0000000098722659</instrumentID>
				</source>
			</header>
			<scanAxisCenter>
				<position axis="2Theta" unit="deg">76.0000</position>
				<position axis="Omega" unit="deg">20.9466</position>
			</scanAxisCenter>
			<reflection>
				<material>SrTiO3</material>
				<hkl>
					<h>0</h>
					<k>1</k>
					<l>3</l>
				</hkl>
			</reflection>
			<dataPoints>
				<positions axis="2Theta" unit="deg">
					<startPosition>73.0400</startPosition>
					<endPosition>78.9600</endPosition>
				</positions>
				<positions axis="Omega" unit="deg">
					<startPosition>19.4666</startPosition>
					<endPosition>22.4266</endPosition>
				</positions>
				<positions axis="Phi" unit="deg">
					<commonPosition>0.00</commonPosition>
				</positions>
				<positions axis="Psi" unit="deg">
					<commonPosition>-0.40</commonPosition>
				</positions>
				<positions axis="X" unit="mm">
					<commonPosition>2.37</commonPosition>
				</positions>
				<positions axis="Y" unit="mm">
					<commonPosition>-0.98</commonPosition>
				</positions>
				<positions axis="Z" unit="mm">
					<commonPosition>9.695</commonPosition>
				</positions>
				<beamAttenuationFactors>1.00 1.00 1.00 1.00 1.00 1.00 1.00 1.00 1.00 1.00 1.00 1.00 1.00 1.00 1.00 1.00 1.00 1.00 1.00 1.00 1.00 1.00 1.00 1.00 1.00 1.00 1.00 1.00 1.00 1.00 1.00 1.00 1.00 1.00 1.00 1.00 1.00 1.00 1.00 1.00 1.00 1.00 1.00 1.00 1.00 1.00 1.00 1.00 1.00 1.00 1.00 1.00 1.00 1.00 1.00 1.00 1.00 1.00 1.00 1.00 1.00 1.00 1.00 1.00 1.00 1.00 1.00 1.00 1.00 1.00 1.00 1.00 1.00 1.00 1.00</beamAttenuationFactors>
				<commonCountingTime unit="seconds">3.00</commonCountingTime>
				<intensities unit="counts">2 8 6 6 3 8 4 4 3 5 9 1 3 2 6 6 3 8 7 5 15 7 10 8 6 12 7 7 10 8 11 8 5 6 5 5 1 6 9 5 7 4 6 7 13 8 8 11 3 5 18 14 16 13 5 7 7 6 7 8 13 2 7 6 3 6 6 10 4 6 8 7 6 7 2</intensities>
			</dataPoints>
		</scan>
		<scan appendNumber="0" mode="Continuous" scanAxis="Omega-2Theta" status="Completed">
			<header>
				<startTimeStamp>2011-04-25T21:07:51+02:00</startTimeStamp>
				<endTimeStamp>2011-04-25T21:12:03+02:00</endTimeStamp>
				<author>
					<name>Mesures</name>
				</author>
				<source>
					<applicationSoftware version="2.0e">X'Pert Data Collector</applicationSoftware>
					<instrumentControlSoftware version="1.5 ">XPERT-PRO</instrumentControlSoftware>
					<instrumentID>0000000098722659</instrumentID>
				</source>
			</header>
			<scanAxisCenter>
				<position axis="2Theta" unit="deg">76.0000</position>
				<position axis="Omega" unit="deg">20.9866</position>
			</scanAxisCenter>
			<reflection>
				<material>SrTiO3</material>
				<hkl>
					<h>0</h>
					<k>1</k>
					<l>3</l>
				</hkl>
			</reflection>
			<dataPoints>
				<positions axis="2Theta" unit="deg">
					<startPosition>73.0400</startPosition>
					<endPosition>78.9600</endPosition>
				</positions>
				<positions axis="Omega" unit="deg">
					<startPosition>19.5066</startPosition>
					<endPosition>22.4666</endPosition>
				</positions>
				<positions axis="Phi" unit="deg">
					<commonPosition>0.00</commonPosition>
				</positions>
				<positions axis="Psi" unit="deg">
					<commonPosition>-0.40</commonPosition>
				</positions>
				<positions axis="X" unit="mm">
					<commonPosition>2.37</commonPosition>
				</positions>
				<positions axis="Y" unit="mm">
					<commonPosition>-0.98</commonPosition>
				</positions>
				<positions axis="Z" unit="mm">
					<commonPosition>9.695</commonPosition>
				</positions>
				<beamAttenuationFactors>1.00 1.00 1.00 1.00 1.00 1.00 1.00 1.00 1.00 1.00 1.00 1.00 1.00 1.00 1.00 1.00 1.00 1.00 1.00 1.00 1.00 1.00 1.00 1.00 1.00 1.00 1.00 1.00 1.00 1.00 1.00 1.00 1.00 1.00 1.00 1.00 1.00 1.00 1.00 1.00 1.00 1.00 1.00 1.00 1.00 1.00 1.00 1.00 1.00 1.00 1.00 1.00 1.00 1.00 1.00 1.00 1.00 1.00 1.00 1.00 1.00 1.00 1.00 1.00 1.00 1.00 1.00 1.00 1.00 1.00 1.00 1.00 1.00 1.00 1.00</beamAttenuationFactors>
				<commonCountingTime unit="seconds">3.00</commonCountingTime>
				<intensities unit="counts">4 5 2 10 5 4 5 6 1 3 3 4 7 5 5 1 3 5 5 4 3 2 5 5 8 7 7 3 4 5 7 7 6 5 11 3 6 5 6 4 6 3 4 7 4 9 10 5 7 9 15 24 11 10 7 8 5 6 3 11 6 6 9 10 10 6 6 5 6 9 5 6 5 7 3</intensities>
			</dataPoints>
		</scan>
		<scan appendNumber="0" mode="Continuous" scanAxis="Omega-2Theta" status="Completed">
			<header>
				<startTimeStamp>2011-04-25T21:12:21+02:00</startTimeStamp>
				<endTimeStamp>2011-04-25T21:16:32+02:00</endTimeStamp>
				<author>
					<name>Mesures</name>
				</author>
				<source>
					<applicationSoftware version="2.0e">X'Pert Data Collector</applicationSoftware>
					<instrumentControlSoftware version="1.5 ">XPERT-PRO</instrumentControlSoftware>
					<instrumentID>0000000098722659</instrumentID>
				</source>
			</header>
			<scanAxisCenter>
				<position axis="2Theta" unit="deg">76.0000</position>
				<position axis="Omega" unit="deg">21.0266</position>
			</scanAxisCenter>
			<reflection>
				<material>SrTiO3</material>
				<hkl>
					<h>0</h>
					<k>1</k>
					<l>3</l>
				</hkl>
			</reflection>
			<dataPoints>
				<positions axis="2Theta" unit="deg">
					<startPosition>73.0400</startPosition>
					<endPosition>78.9600</endPosition>
				</positions>
				<positions axis="Omega" unit="deg">
					<startPosition>19.5466</startPosition>
					<endPosition>22.5066</endPosition>
				</positions>
				<positions axis="Phi" unit="deg">
					<commonPosition>0.00</commonPosition>
				</positions>
				<positions axis="Psi" unit="deg">
					<commonPosition>-0.40</commonPosition>
				</positions>
				<positions axis="X" unit="mm">
					<commonPosition>2.37</commonPosition>
				</positions>
				<positions axis="Y" unit="mm">
					<commonPosition>-0.98</commonPosition>
				</positions>
				<positions axis="Z" unit="mm">
					<commonPosition>9.695</commonPosition>
				</positions>
				<beamAttenuationFactors>1.00 1.00 1.00 1.00 1.00 1.00 1.00 1.00 1.00 1.00 1.00 1.00 1.00 1.00 1.00 1.00 1.00 1.00 1.00 1.00 1.00 1.00 1.00 1.00 1.00 1.00 1.00 1.00 1.00 1.00 1.00 1.00 1.00 1.00 1.00 1.00 1.00 1.00 1.00 1.00 1.00 1.00 1.00 1.00 1.00 1.00 1.00 1.00 1.00 1.00 1.00 1.00 1.00 1.00 1.00 1.00 1.00 1.00 1.00 1.00 1.00 1.00 1.00 1.00 1.00 1.00 1.00 1.00 1.00 1.00 1.00 1.00 1.00 1.00 1.00</beamAttenuationFactors>
				<commonCountingTime unit="seconds">3.00</commonCountingTime>
				<intensities unit="counts">3 1 3 5 3 2 3 3 4 7 4 5 6 2 2 5 6 3 4 7 5 9 5 2 5 5 9 9 7 9 2 3 5 4 9 6 5 7 1 6 11 7 8 7 5 7 9 6 9 11 16 7 17 13 12 9 8 9 8 4 5 5 10 8 8 6 12 10 6 6 3 4 5 5 9</intensities>
			</dataPoints>
		</scan>
		<scan appendNumber="0" mode="Continuous" scanAxis="Omega-2Theta" status="Completed">
			<header>
				<startTimeStamp>2011-04-25T21:16:44+02:00</startTimeStamp>
				<endTimeStamp>2011-04-25T21:20:53+02:00</endTimeStamp>
				<author>
					<name>Mesures</name>
				</author>
				<source>
					<applicationSoftware version="2.0e">X'Pert Data Collector</applicationSoftware>
					<instrumentControlSoftware version="1.5 ">XPERT-PRO</instrumentControlSoftware>
					<instrumentID>0000000098722659</instrumentID>
				</source>
			</header>
			<scanAxisCenter>
				<position axis="2Theta" unit="deg">76.0000</position>
				<position axis="Omega" unit="deg">21.0666</position>
			</scanAxisCenter>
			<reflection>
				<material>SrTiO3</material>
				<hkl>
					<h>0</h>
					<k>1</k>
					<l>3</l>
				</hkl>
			</reflection>
			<dataPoints>
				<positions axis="2Theta" unit="deg">
					<startPosition>73.0400</startPosition>
					<endPosition>78.9600</endPosition>
				</positions>
				<positions axis="Omega" unit="deg">
					<startPosition>19.5866</startPosition>
					<endPosition>22.5466</endPosition>
				</positions>
				<positions axis="Phi" unit="deg">
					<commonPosition>0.00</commonPosition>
				</positions>
				<positions axis="Psi" unit="deg">
					<commonPosition>-0.40</commonPosition>
				</positions>
				<positions axis="X" unit="mm">
					<commonPosition>2.37</commonPosition>
				</positions>
				<positions axis="Y" unit="mm">
					<commonPosition>-0.98</commonPosition>
				</positions>
				<positions axis="Z" unit="mm">
					<commonPosition>9.695</commonPosition>
				</positions>
				<beamAttenuationFactors>1.00 1.00 1.00 1.00 1.00 1.00 1.00 1.00 1.00 1.00 1.00 1.00 1.00 1.00 1.00 1.00 1.00 1.00 1.00 1.00 1.00 1.00 1.00 1.00 1.00 1.00 1.00 1.00 1.00 1.00 1.00 1.00 1.00 1.00 1.00 1.00 1.00 1.00 1.00 1.00 1.00 1.00 1.00 1.00 1.00 1.00 1.00 1.00 1.00 1.00 1.00 1.00 1.00 1.00 1.00 1.00 1.00 1.00 1.00 1.00 1.00 1.00 1.00 1.00 1.00 1.00 1.00 1.00 1.00 1.00 1.00 1.00 1.00 1.00 1.00</beamAttenuationFactors>
				<commonCountingTime unit="seconds">3.00</commonCountingTime>
				<intensities unit="counts">3 4 4 4 4 1 5 5 3 3 3 7 4 4 7 4 4 6 4 4 5 4 11 9 4 5 11 3 6 6 6 5 9 3 7 5 1 2 3 6 7 7 8 5 8 9 8 8 7 9 11 13 11 11 8 4 8 4 5 3 3 2 9 5 9 5 8 5 5 8 6 6 5 6 4</intensities>
			</dataPoints>
		</scan>
	</xrdMeasurement>
</xrdMeasurements>